#VRML_SIM R2023a utf8

EXTERNPROTO "https://raw.githubusercontent.com/cyberbotics/webots/R2023a/projects/objects/backgrounds/protos/TexturedBackground.proto"
EXTERNPROTO "https://raw.githubusercontent.com/cyberbotics/webots/R2023a/projects/objects/backgrounds/protos/TexturedBackgroundLight.proto"
EXTERNPROTO "https://raw.githubusercontent.com/cyberbotics/webots/R2023a/projects/objects/floors/protos/RectangleArena.proto"
EXTERNPROTO "https://raw.githubusercontent.com/cyberbotics/webots/R2023a/projects/appearances/protos/Parquetry.proto"

WorldInfo {
}
Viewpoint {
  orientation -0.3291357485251547 -0.00809810775556088 0.9442478910188603 3.1880577350970256
  position 0.3845563741064907 -0.025085956133022926 0.3547695634852262
}
TexturedBackground {
}
TexturedBackgroundLight {
}
RectangleArena {
  translation 0 0 0.02
  floorAppearance Parquetry {
    type "light strip"
  }
}
Robot {
  translation 0 -0.01 0.05
  rotation 0 1 0 0
  children [
    DEF Innerbody Shape {
      appearance PBRAppearance {
        baseColor 0.2 0.6 0.5
        metalness 0
      }
      geometry Box {
        size 0.1 0.1 0.053
      }
    }
    Shape {
    }
    HingeJoint {
      jointParameters HingeJointParameters {
        axis 0 1 0
        anchor 4.0451e-17 0.059996 -7.19059e-06
      }
      device [
        RotationalMotor {
          name "wheel1"
        }
      ]
      endPoint Solid {
        translation -9e-08 0.056 -1.122e-05
        rotation 1 -5.937369089988011e-16 -5.77152022682736e-16 1.5708
        children [
          DEF Wheel Shape {
            appearance PBRAppearance {
              baseColor 0.2 0.1 0.1
              metalness 0
            }
            geometry Cylinder {
              height 0.01
              radius 0.03
            }
          }
        ]
      }
    }
    HingeJoint {
      jointParameters HingeJointParameters {
        axis 0 1 0
        anchor -9e-08 -0.060004 -1.16604e-05
      }
      device [
        RotationalMotor {
          name "wheel2"
        }
      ]
      endPoint Solid {
        translation -9e-08 -0.056 -3.65633e-05
        rotation 1 -5.937369089988011e-16 -5.77152022682736e-16 1.5708
        children [
          DEF Wheel Shape {
            appearance PBRAppearance {
              baseColor 0.2 0.1 0.1
              metalness 0
            }
            geometry Cylinder {
              height 0.01
              radius 0.03
            }
          }
        ]
        name "solid(1)"
      }
    }
    TouchSensor {
      translation 0.05 0.05 0
      rotation 0.3574040741052406 -0.8628571789074145 -0.35740707410586264 -1.7177753071795863
      children [
        DEF Sensor Shape {
          appearance PBRAppearance {
            baseColor 0.4 0.2 0.1
            metalness 0
          }
          geometry DEF Sensor Cone {
            bottomRadius 0.01
            height 0.01
          }
        }
      ]
      name "touch sensor 1"
      physics Physics {
      }
    }
    TouchSensor {
      translation 0.05 -0.05 -9.99999e-08
      rotation 0.35740699927911007 0.8628559982596194 -0.35740699927911007 1.71778
      children [
        DEF Sensor Shape {
          appearance PBRAppearance {
            baseColor 0.4 0.2 0.1
            metalness 0
          }
          geometry Cone {
            bottomRadius 0.01
            height 0.01
          }
        }
      ]
      name "touch sensor 2"
      physics Physics {
      }
    }
  ]
  boundingObject USE Innerbody
  physics Physics {
  }
  controller "first_obd_controller"
}
