#VRML_SIM R2023a utf8

EXTERNPROTO "https://raw.githubusercontent.com/cyberbotics/webots/R2023a/projects/objects/backgrounds/protos/TexturedBackground.proto"
EXTERNPROTO "https://raw.githubusercontent.com/cyberbotics/webots/R2023a/projects/objects/backgrounds/protos/TexturedBackgroundLight.proto"
EXTERNPROTO "https://raw.githubusercontent.com/cyberbotics/webots/R2023a/projects/objects/floors/protos/RectangleArena.proto"
EXTERNPROTO "https://raw.githubusercontent.com/cyberbotics/webots/R2023a/projects/appearances/protos/Parquetry.proto"

WorldInfo {
}
Viewpoint {
  orientation -0.18911301291294058 -0.03825555420043472 0.9812098556984674 3.533490831580436
  position 1.136314940477286 0.4674077317003685 0.6174184190334224
}
TexturedBackground {
}
TexturedBackgroundLight {
}
RectangleArena {
  translation 0 0 0.02
  floorAppearance Parquetry {
    type "light strip"
  }
}
Robot {
  translation 0 -0.01 0.05
  rotation 0 1 0 0
  children [
    DEF Innerbody Shape {
      appearance PBRAppearance {
        baseColor 0.2 0.6 0.5
        metalness 0
      }
      geometry Box {
        size 0.1 0.1 0.053
      }
    }
    Shape {
    }
    HingeJoint {
      jointParameters HingeJointParameters {
        axis 0 1 0
        anchor 4.0451e-17 0.059996 -7.19059e-06
      }
      device [
        RotationalMotor {
          name "wheel1"
        }
      ]
      endPoint Solid {
        translation -9e-08 0.056 -1.122e-05
        rotation 1 -5.937369089988011e-16 -5.77152022682736e-16 1.5708
        children [
          DEF Wheel Shape {
            appearance PBRAppearance {
              baseColor 0.2 0.1 0.1
              metalness 0
            }
            geometry Cylinder {
              height 0.01
              radius 0.03
            }
          }
        ]
        boundingObject USE Wheel
        physics Physics {
        }
      }
    }
    HingeJoint {
      jointParameters HingeJointParameters {
        axis 0 1 0
        anchor -9e-08 -0.060004 -1.16604e-05
      }
      device [
        RotationalMotor {
          name "wheel2"
        }
      ]
      endPoint Solid {
        translation -9e-08 -0.056 -3.65633e-05
        rotation 1 -5.937369089988011e-16 -5.77152022682736e-16 1.5708
        children [
          DEF Wheel Shape {
            appearance PBRAppearance {
              baseColor 0.2 0.1 0.1
              metalness 0
            }
            geometry Cylinder {
              height 0.01
              radius 0.03
            }
          }
        ]
        name "solid(1)"
        boundingObject USE Wheel
        physics Physics {
        }
      }
    }
    TouchSensor {
      translation 0.05 0.05 0
      rotation 0.3574040741052406 -0.8628571789074145 -0.35740707410586264 -1.7177753071795863
      children [
        DEF Sensor Shape {
          appearance PBRAppearance {
            baseColor 0.3 0.6 1
            metalness 0
          }
          geometry Sphere {
            radius 0.007
          }
        }
      ]
      name "touch sensor 1"
      boundingObject USE Sensor
      physics Physics {
      }
    }
    TouchSensor {
      translation 0.05 -0.05 -9.99999e-08
      rotation 0.35740699927911007 0.8628559982596194 -0.35740699927911007 1.71778
      children [
        DEF Sensor Shape {
          appearance PBRAppearance {
            baseColor 0.3 0.6 1
          }
          geometry Sphere {
            radius 0.007
          }
        }
      ]
      name "touch sensor 2"
      boundingObject USE Sensor
      physics Physics {
      }
    }
  ]
  boundingObject USE Innerbody
  physics Physics {
  }
  controller "first_obd_controller"
}
