#VRML_SIM R2023a utf8

EXTERNPROTO "https://raw.githubusercontent.com/cyberbotics/webots/R2023a/projects/objects/backgrounds/protos/TexturedBackground.proto"
EXTERNPROTO "https://raw.githubusercontent.com/cyberbotics/webots/R2023a/projects/objects/backgrounds/protos/TexturedBackgroundLight.proto"
EXTERNPROTO "https://raw.githubusercontent.com/cyberbotics/webots/R2023a/projects/objects/floors/protos/RectangleArena.proto"

WorldInfo {
}
Viewpoint {
  orientation 0.35720384331342114 -0.02576073293195797 -0.9336711406919083 3.276050264949714
  position 0.7025842427082403 -0.31993649518519174 0.9009857603885822
}
TexturedBackground {
}
TexturedBackgroundLight {
}
RectangleArena {
}
Robot {
  translation 0 -0.01 0.05
  children [
    DEF Body Shape {
      appearance PBRAppearance {
        baseColor 0.2 0.6 0.5
        metalness 0
      }
      geometry Box {
        size 0.1 0.1 0.05
      }
    }
    HingeJoint {
      jointParameters HingeJointParameters {
      }
      device [
        RotationalMotor {
          name "wheel1"
        }
      ]
      endPoint Solid {
        translation 4.0450986678541455e-17 0.05999602321367749 -7.190587383521972e-06
        rotation 1 -5.937369089988011e-16 -5.77152022682736e-16 1.5708
        children [
          DEF Wheel Shape {
            appearance PBRAppearance {
            }
            geometry Cylinder {
              height 0.01
              radius 0.03
            }
          }
        ]
      }
    }
  ]
}
